Traceback (most recent call last):
  File "/export/home1/PROJECTS/argobathy/deep/corrected_positions_pool.py", line 68, in <module>
    results0 = pool0.map(get_coords_corrected_glo, df1.N_GRD.values)
  File "/export/home1/OTHER/miniconda/envs/virtualfleet-v3/lib/python3.9/multiprocessing/pool.py", line 364, in map
    return self._map_async(func, iterable, mapstar, chunksize).get()
  File "/export/home1/OTHER/miniconda/envs/virtualfleet-v3/lib/python3.9/multiprocessing/pool.py", line 771, in get
    raise self._value
multiprocessing.pool.MaybeEncodingError: Error sending result: '<multiprocessing.pool.ExceptionWithTraceback object at 0x7fe3ee1769d0>'. Reason: 'TypeError("cannot pickle '_io.BufferedReader' object")'
0
100
200
300
400
500
600
700
800
900
1000
1100
1200
some kind of error with  1237
1300
1400
1500
1600
1700
1800
1900
2000
2100
2200
2300
2400
2500
2600
2700
2800
2900
3000
3100
3200
3300
3400
3500
some kind of error with  3582
3600
some kind of error with  3610
3700
3800
3900
0
100
200
300
400
500
600
700
800
900
1000
1100
1200
1300
1400
1500
1600
1700
1800
1900
2000
2100
2200
2300
2400
2500
2600
2700
2800
2900
3000
3100
3200
3300
3400
3500
3600
3700
3800
3900
